ctit080
2024-05-23 13:56:15,266	ERROR services.py:1207 -- Failed to start the dashboard 
2024-05-23 13:56:15,273	ERROR services.py:1232 -- Error should be written to 'dashboard.log' or 'dashboard.err'. We are printing the last 20 lines for you. See 'https://docs.ray.io/en/master/ray-observability/ray-logging.html#logging-directory-structure' to find where the log file is.
2024-05-23 13:56:15,273	ERROR services.py:1242 -- Couldn't read dashboard.log file. Error: [Errno 2] No such file or directory: '/local/ray/session_2024-05-23_13-55-49_404658_3253617/logs/dashboard.log'. It means the dashboard is broken even before it initializes the logger (mostly dependency issues). Reading the dashboard.err file which contains stdout/stderr.
2024-05-23 13:56:15,273	ERROR services.py:1276 -- Failed to read dashboard.err file: cannot mmap an empty file. It is unexpected. Please report an issue to Ray github. https://github.com/ray-project/ray/issues
2024-05-23 13:55:49,304	INFO usage_lib.py:412 -- Usage stats collection is enabled. To disable this, add `--disable-usage-stats` to the command that starts the cluster, or run the following command: `ray disable-usage-stats` before starting the cluster. See https://docs.ray.io/en/master/cluster/usage-stats.html for more details.
2024-05-23 13:55:49,305	INFO scripts.py:722 -- Local node IP: 10.20.240.10
2024-05-23 13:56:18,844	SUCC scripts.py:759 -- --------------------
2024-05-23 13:56:18,844	SUCC scripts.py:760 -- Ray runtime started.
2024-05-23 13:56:18,844	SUCC scripts.py:761 -- --------------------
2024-05-23 13:56:18,844	INFO scripts.py:763 -- Next steps
2024-05-23 13:56:18,844	INFO scripts.py:766 -- To add another node to this Ray cluster, run
2024-05-23 13:56:18,844	INFO scripts.py:769 --   ray start --address='10.20.240.10:6379'
2024-05-23 13:56:18,844	INFO scripts.py:778 -- To connect to this Ray cluster:
2024-05-23 13:56:18,844	INFO scripts.py:780 -- import ray
2024-05-23 13:56:18,844	INFO scripts.py:781 -- ray.init()
2024-05-23 13:56:18,845	INFO scripts.py:812 -- To terminate the Ray runtime, run
2024-05-23 13:56:18,845	INFO scripts.py:813 --   ray stop
2024-05-23 13:56:18,845	INFO scripts.py:816 -- To view the status of the cluster, use
2024-05-23 13:56:18,845	INFO scripts.py:817 --   ray status
2024-05-23 13:58:17.643083: I tensorflow/core/platform/cpu_feature_guard.cc:210] This TensorFlow binary is optimized to use available CPU instructions in performance-critical operations.
To enable the following instructions: AVX2 FMA, in other operations, rebuild TensorFlow with the appropriate compiler flags.
2024-05-23 13:58:23.811799: W tensorflow/compiler/tf2tensorrt/utils/py_utils.cc:38] TF-TRT Warning: Could not find TensorRT
INFO flwr 2024-05-23 13:58:52,062 | Data.py:31 | Preprocessing the federated learning dataset
INFO flwr 2024-05-23 13:58:52,111 | Data.py:107 | Found preprocessed data for the given preprocess function, returning
INFO flwr 2024-05-23 13:59:08,872 | Simulation.py:37 | Preparing datasets for federated learning simulation
INFO flwr 2024-05-23 13:59:08,912 | Simulation.py:255 | Found previously split dataloaders, loading them
INFO flwr 2024-05-23 13:59:41,824 | main.py:103 | Loaded 1 configs with name PURCHASE-FCN-FEDADAM, running...
INFO flwr 2024-05-23 13:59:41,826 | main.py:105 | Config:
	Simulation:
		Data:
			dataset_name: purchase
			batch_size: 16
			preprocess_fn:
				def preprocess_fn(element):
				  return {
				    "x": element["features"],
				    "y": element["label"]
				  }
		Federation:
			client_count: 100
			fraction_fit: 0.1
			global_rounds: 2
			local_rounds: 20
		Model:
			optimizer_name: FedAdam
			model_name: FCN
			criterion_name: CrossEntropyLoss
			optimizer_parameters: 
				local: {'lr': 0.25}
				global: {'lr': 0.01, 'betas': [0.9, 0.999], 'eps': 1e-08, 'weight_decay': 0.9999}
			model_architecture:
				type: Linear
					in_features: 600
					out_features: 200
				type: Tanh
				type: Linear
					in_features: 200
					out_features: 128
				type: Tanh
				type: Linear
					in_features: 128
					out_features: 100
				type: Softmax
					dim: -1
	Attack:
		data_access: all
		message_access: server
		repetitions: 10
		Attack Simulation:
			batch_size: 64
			optimizer_name: FedAvg
			optimizer_parameters:
				lr: 0.1
			ModelArchitecture:
				gradient_component:
					type: Dropout
						p: 0.2
					type: Conv3d
						out_channels: 1000
						kernel_size: [1, 1]
						stride: 1
					type: ReLU
				fcn_component:
					type: Dropout
						p: 0.2
					type: Linear
						out_features: 128
					type: ReLU
					type: Dropout
						p: 0.2
					type: Linear
						in_features: 128
						out_features: 64
					type: ReLU
				encoder_component:
					type: Dropout
						p: 0.2
					type: Linear
						out_features: 256
					type: ReLU
					type: Dropout
						p: 0.2
					type: Linear
						in_features: 256
						out_features: 128
					type: ReLU
					type: Dropout
						p: 0.2
					type: Linear
						in_features: 128
						out_features: 64
					type: ReLU
					type: Dropout
						p: 0.2
					type: Linear
						in_features: 64
						out_features: 1
					type: ReLU
					type: Sigmoid
INFO flwr 2024-05-23 13:59:41,839 | Config.py:68 | Starting conFEDential simulation
INFO flwr 2024-05-23 13:59:41,926 | Config.py:72 | No previous federated learning simulation found, starting training simulation...
Traceback (most recent call last):
  File "/home/s2240084/conFEDential/src/main.py", line 112, in <module>
    main()
  File "/home/s2240084/conFEDential/src/main.py", line 106, in main
    config.run_simulation(
  File "/home/s2240084/conFEDential/src/experiment/Config.py", line 73, in run_simulation
    self.simulation.simulate_federation(
  File "/home/s2240084/conFEDential/src/experiment/Simulation.py", line 157, in simulate_federation
    wandb.init(mode=mode, **wandb_kwargs)
  File "/home/s2240084/conFEDential/venv/lib/python3.10/site-packages/wandb/sdk/wandb_init.py", line 1206, in init
    raise e
  File "/home/s2240084/conFEDential/venv/lib/python3.10/site-packages/wandb/sdk/wandb_init.py", line 1183, in init
    wi.setup(kwargs)
  File "/home/s2240084/conFEDential/venv/lib/python3.10/site-packages/wandb/sdk/wandb_init.py", line 190, in setup
    self._wl = wandb_setup.setup(settings=setup_settings)
  File "/home/s2240084/conFEDential/venv/lib/python3.10/site-packages/wandb/sdk/wandb_setup.py", line 327, in setup
    ret = _setup(settings=settings)
  File "/home/s2240084/conFEDential/venv/lib/python3.10/site-packages/wandb/sdk/wandb_setup.py", line 320, in _setup
    wl = _WandbSetup(settings=settings)
  File "/home/s2240084/conFEDential/venv/lib/python3.10/site-packages/wandb/sdk/wandb_setup.py", line 303, in __init__
    _WandbSetup._instance = _WandbSetup__WandbSetup(settings=settings, pid=pid)
  File "/home/s2240084/conFEDential/venv/lib/python3.10/site-packages/wandb/sdk/wandb_setup.py", line 114, in __init__
    self._setup()
  File "/home/s2240084/conFEDential/venv/lib/python3.10/site-packages/wandb/sdk/wandb_setup.py", line 250, in _setup
    self._setup_manager()
  File "/home/s2240084/conFEDential/venv/lib/python3.10/site-packages/wandb/sdk/wandb_setup.py", line 277, in _setup_manager
    self._manager = wandb_manager._Manager(settings=self._settings)
  File "/home/s2240084/conFEDential/venv/lib/python3.10/site-packages/wandb/sdk/wandb_manager.py", line 139, in __init__
    self._service.start()
  File "/home/s2240084/conFEDential/venv/lib/python3.10/site-packages/wandb/sdk/service/service.py", line 250, in start
    self._launch_server()
  File "/home/s2240084/conFEDential/venv/lib/python3.10/site-packages/wandb/sdk/service/service.py", line 244, in _launch_server
    _sentry.reraise(e)
  File "/home/s2240084/conFEDential/venv/lib/python3.10/site-packages/wandb/analytics/sentry.py", line 154, in reraise
    raise exc.with_traceback(sys.exc_info()[2])
  File "/home/s2240084/conFEDential/venv/lib/python3.10/site-packages/wandb/sdk/service/service.py", line 242, in _launch_server
    self._wait_for_ports(fname, proc=internal_proc)
  File "/home/s2240084/conFEDential/venv/lib/python3.10/site-packages/wandb/sdk/service/service.py", line 132, in _wait_for_ports
    raise ServiceStartTimeoutError(
wandb.sdk.service.service.ServiceStartTimeoutError: Timed out waiting for wandb service to start after 30.0 seconds. Try increasing the timeout with the `_service_wait` setting.
Traceback (most recent call last):
  File "/deepstore/software/python/3.10.7/lib/python3.10/runpy.py", line 196, in _run_module_as_main
    return _run_code(code, main_globals, None,
  File "/deepstore/software/python/3.10.7/lib/python3.10/runpy.py", line 86, in _run_code
    exec(code, run_globals)
  File "/home/s2240084/conFEDential/venv/lib/python3.10/site-packages/wandb/__main__.py", line 3, in <module>
    cli.cli(prog_name="python -m wandb")
  File "/home/s2240084/conFEDential/venv/lib/python3.10/site-packages/click/core.py", line 1157, in __call__
    return self.main(*args, **kwargs)
  File "/home/s2240084/conFEDential/venv/lib/python3.10/site-packages/click/core.py", line 1078, in main
    rv = self.invoke(ctx)
  File "/home/s2240084/conFEDential/venv/lib/python3.10/site-packages/click/core.py", line 1688, in invoke
    return _process_result(sub_ctx.command.invoke(sub_ctx))
  File "/home/s2240084/conFEDential/venv/lib/python3.10/site-packages/click/core.py", line 1434, in invoke
    return ctx.invoke(self.callback, **ctx.params)
  File "/home/s2240084/conFEDential/venv/lib/python3.10/site-packages/click/core.py", line 783, in invoke
    return __callback(*args, **kwargs)
  File "/home/s2240084/conFEDential/venv/lib/python3.10/site-packages/wandb/cli/cli.py", line 105, in wrapper
    return func(*args, **kwargs)
  File "/home/s2240084/conFEDential/venv/lib/python3.10/site-packages/wandb/cli/cli.py", line 289, in service
    server.serve()
  File "/home/s2240084/conFEDential/venv/lib/python3.10/site-packages/wandb/sdk/service/server.py", line 114, in serve
    self._inform_used_ports(sock_port=sock_port)
  File "/home/s2240084/conFEDential/venv/lib/python3.10/site-packages/wandb/sdk/service/server.py", line 52, in _inform_used_ports
    pf.write(self._port_fname)
  File "/home/s2240084/conFEDential/venv/lib/python3.10/site-packages/wandb/sdk/service/port_file.py", line 21, in write
    f = tempfile.NamedTemporaryFile(prefix=bname, dir=dname, mode="w", delete=False)
  File "/deepstore/software/python/3.10.7/lib/python3.10/tempfile.py", line 559, in NamedTemporaryFile
    file = _io.open(dir, mode, buffering=buffering,
  File "/deepstore/software/python/3.10.7/lib/python3.10/tempfile.py", line 556, in opener
    fd, name = _mkstemp_inner(dir, prefix, suffix, flags, output_type)
  File "/deepstore/software/python/3.10.7/lib/python3.10/tempfile.py", line 256, in _mkstemp_inner
    fd = _os.open(file, flags, 0o600)
FileNotFoundError: [Errno 2] No such file or directory: '/tmp/tmpqv52hjwb/port-3253819.txtvkablx74'
srun: error: ctit080: task 0: Exited with exit code 1
2024-05-23 14:01:34.906914: I tensorflow/core/platform/cpu_feature_guard.cc:210] This TensorFlow binary is optimized to use available CPU instructions in performance-critical operations.
To enable the following instructions: AVX2 FMA, in other operations, rebuild TensorFlow with the appropriate compiler flags.
2024-05-23 14:01:38.592272: W tensorflow/compiler/tf2tensorrt/utils/py_utils.cc:38] TF-TRT Warning: Could not find TensorRT
INFO flwr 2024-05-23 14:01:58,704 | Data.py:31 | Preprocessing the federated learning dataset
INFO flwr 2024-05-23 14:01:58,705 | Data.py:107 | Found preprocessed data for the given preprocess function, returning
INFO flwr 2024-05-23 14:01:58,738 | Simulation.py:37 | Preparing datasets for federated learning simulation
INFO flwr 2024-05-23 14:01:58,782 | Simulation.py:255 | Found previously split dataloaders, loading them
INFO flwr 2024-05-23 14:02:29,119 | main.py:103 | Loaded 1 configs with name PURCHASE-FCN-FEDAVG, running...
INFO flwr 2024-05-23 14:02:29,122 | main.py:105 | Config:
	Simulation:
		Data:
			dataset_name: purchase
			batch_size: 8
			preprocess_fn:
				def preprocess_fn(element):
				  return {
				    "x": element["features"],
				    "y": element["label"]
				  }
		Federation:
			client_count: 100
			fraction_fit: 0.1
			global_rounds: 2
			local_rounds: 20
		Model:
			optimizer_name: FedAvg
			model_name: FCN
			criterion_name: CrossEntropyLoss
			optimizer_parameters: 
				lr: 0.25
			model_architecture:
				type: Linear
					in_features: 600
					out_features: 200
				type: Tanh
				type: Linear
					in_features: 200
					out_features: 128
				type: Tanh
				type: Linear
					in_features: 128
					out_features: 100
				type: Softmax
					dim: -1
	Attack:
		data_access: all
		message_access: server
		repetitions: 10
		Attack Simulation:
			batch_size: 64
			optimizer_name: FedAvg
			optimizer_parameters:
				lr: 0.1
			ModelArchitecture:
				gradient_component:
					type: Dropout
						p: 0.2
					type: Conv3d
						out_channels: 1000
						kernel_size: [1, 1]
						stride: 1
					type: ReLU
				fcn_component:
					type: Dropout
						p: 0.2
					type: Linear
						out_features: 128
					type: ReLU
					type: Dropout
						p: 0.2
					type: Linear
						in_features: 128
						out_features: 64
					type: ReLU
				encoder_component:
					type: Dropout
						p: 0.2
					type: Linear
						out_features: 256
					type: ReLU
					type: Dropout
						p: 0.2
					type: Linear
						in_features: 256
						out_features: 128
					type: ReLU
					type: Dropout
						p: 0.2
					type: Linear
						in_features: 128
						out_features: 64
					type: ReLU
					type: Dropout
						p: 0.2
					type: Linear
						in_features: 64
						out_features: 1
					type: ReLU
					type: Sigmoid
INFO flwr 2024-05-23 14:02:29,136 | Config.py:68 | Starting conFEDential simulation
INFO flwr 2024-05-23 14:02:29,140 | Config.py:72 | No previous federated learning simulation found, starting training simulation...
Traceback (most recent call last):
  File "/home/s2240084/conFEDential/src/main.py", line 112, in <module>
    main()
  File "/home/s2240084/conFEDential/src/main.py", line 106, in main
    config.run_simulation(
  File "/home/s2240084/conFEDential/src/experiment/Config.py", line 73, in run_simulation
    self.simulation.simulate_federation(
  File "/home/s2240084/conFEDential/src/experiment/Simulation.py", line 157, in simulate_federation
    wandb.init(mode=mode, **wandb_kwargs)
  File "/home/s2240084/conFEDential/venv/lib/python3.10/site-packages/wandb/sdk/wandb_init.py", line 1206, in init
    raise e
  File "/home/s2240084/conFEDential/venv/lib/python3.10/site-packages/wandb/sdk/wandb_init.py", line 1183, in init
    wi.setup(kwargs)
  File "/home/s2240084/conFEDential/venv/lib/python3.10/site-packages/wandb/sdk/wandb_init.py", line 190, in setup
    self._wl = wandb_setup.setup(settings=setup_settings)
  File "/home/s2240084/conFEDential/venv/lib/python3.10/site-packages/wandb/sdk/wandb_setup.py", line 327, in setup
    ret = _setup(settings=settings)
  File "/home/s2240084/conFEDential/venv/lib/python3.10/site-packages/wandb/sdk/wandb_setup.py", line 320, in _setup
    wl = _WandbSetup(settings=settings)
  File "/home/s2240084/conFEDential/venv/lib/python3.10/site-packages/wandb/sdk/wandb_setup.py", line 303, in __init__
    _WandbSetup._instance = _WandbSetup__WandbSetup(settings=settings, pid=pid)
  File "/home/s2240084/conFEDential/venv/lib/python3.10/site-packages/wandb/sdk/wandb_setup.py", line 114, in __init__
    self._setup()
  File "/home/s2240084/conFEDential/venv/lib/python3.10/site-packages/wandb/sdk/wandb_setup.py", line 250, in _setup
    self._setup_manager()
  File "/home/s2240084/conFEDential/venv/lib/python3.10/site-packages/wandb/sdk/wandb_setup.py", line 277, in _setup_manager
    self._manager = wandb_manager._Manager(settings=self._settings)
  File "/home/s2240084/conFEDential/venv/lib/python3.10/site-packages/wandb/sdk/wandb_manager.py", line 139, in __init__
    self._service.start()
  File "/home/s2240084/conFEDential/venv/lib/python3.10/site-packages/wandb/sdk/service/service.py", line 250, in start
    self._launch_server()
  File "/home/s2240084/conFEDential/venv/lib/python3.10/site-packages/wandb/sdk/service/service.py", line 244, in _launch_server
    _sentry.reraise(e)
  File "/home/s2240084/conFEDential/venv/lib/python3.10/site-packages/wandb/analytics/sentry.py", line 154, in reraise
    raise exc.with_traceback(sys.exc_info()[2])
  File "/home/s2240084/conFEDential/venv/lib/python3.10/site-packages/wandb/sdk/service/service.py", line 242, in _launch_server
    self._wait_for_ports(fname, proc=internal_proc)
  File "/home/s2240084/conFEDential/venv/lib/python3.10/site-packages/wandb/sdk/service/service.py", line 132, in _wait_for_ports
    raise ServiceStartTimeoutError(
wandb.sdk.service.service.ServiceStartTimeoutError: Timed out waiting for wandb service to start after 30.0 seconds. Try increasing the timeout with the `_service_wait` setting.
srun: error: ctit080: task 0: Exited with exit code 1
2024-05-23 14:03:32.459210: I tensorflow/core/platform/cpu_feature_guard.cc:210] This TensorFlow binary is optimized to use available CPU instructions in performance-critical operations.
To enable the following instructions: AVX2 FMA, in other operations, rebuild TensorFlow with the appropriate compiler flags.
2024-05-23 14:03:35.207098: W tensorflow/compiler/tf2tensorrt/utils/py_utils.cc:38] TF-TRT Warning: Could not find TensorRT
INFO flwr 2024-05-23 14:03:48,371 | Data.py:31 | Preprocessing the federated learning dataset
INFO flwr 2024-05-23 14:03:48,372 | Data.py:107 | Found preprocessed data for the given preprocess function, returning
INFO flwr 2024-05-23 14:03:48,406 | Simulation.py:37 | Preparing datasets for federated learning simulation
INFO flwr 2024-05-23 14:03:48,406 | Simulation.py:255 | Found previously split dataloaders, loading them
INFO flwr 2024-05-23 14:04:14,815 | main.py:103 | Loaded 1 configs with name PURCHASE-FCN-FEDNAG, running...
INFO flwr 2024-05-23 14:04:14,817 | main.py:105 | Config:
	Simulation:
		Data:
			dataset_name: purchase
			batch_size: 8
			preprocess_fn:
				def preprocess_fn(element):
				  return {
				    "x": element["features"],
				    "y": element["label"]
				  }
		Federation:
			client_count: 100
			fraction_fit: 0.1
			global_rounds: 2
			local_rounds: 50
		Model:
			optimizer_name: FedNAG
			model_name: FCN
			criterion_name: CrossEntropyLoss
			optimizer_parameters: 
				lr: 0.01
				momentum: 0.95
			model_architecture:
				type: Linear
					in_features: 600
					out_features: 200
				type: Tanh
				type: Linear
					in_features: 200
					out_features: 128
				type: Tanh
				type: Linear
					in_features: 128
					out_features: 100
				type: Softmax
					dim: -1
	Attack:
		data_access: all
		message_access: server
		repetitions: 10
		Attack Simulation:
			batch_size: 64
			optimizer_name: FedAvg
			optimizer_parameters:
				lr: 0.1
			ModelArchitecture:
				gradient_component:
					type: Dropout
						p: 0.2
					type: Conv3d
						out_channels: 1000
						kernel_size: [1, 1]
						stride: 1
					type: ReLU
				fcn_component:
					type: Dropout
						p: 0.2
					type: Linear
						out_features: 128
					type: ReLU
					type: Dropout
						p: 0.2
					type: Linear
						in_features: 128
						out_features: 64
					type: ReLU
				encoder_component:
					type: Dropout
						p: 0.2
					type: Linear
						out_features: 256
					type: ReLU
					type: Dropout
						p: 0.2
					type: Linear
						in_features: 256
						out_features: 128
					type: ReLU
					type: Dropout
						p: 0.2
					type: Linear
						in_features: 128
						out_features: 64
					type: ReLU
					type: Dropout
						p: 0.2
					type: Linear
						in_features: 64
						out_features: 1
					type: ReLU
					type: Sigmoid
INFO flwr 2024-05-23 14:04:14,833 | Config.py:68 | Starting conFEDential simulation
INFO flwr 2024-05-23 14:04:14,835 | Config.py:72 | No previous federated learning simulation found, starting training simulation...
Traceback (most recent call last):
  File "/home/s2240084/conFEDential/src/main.py", line 112, in <module>
    main()
  File "/home/s2240084/conFEDential/src/main.py", line 106, in main
    config.run_simulation(
  File "/home/s2240084/conFEDential/src/experiment/Config.py", line 73, in run_simulation
    self.simulation.simulate_federation(
  File "/home/s2240084/conFEDential/src/experiment/Simulation.py", line 157, in simulate_federation
    wandb.init(mode=mode, **wandb_kwargs)
  File "/home/s2240084/conFEDential/venv/lib/python3.10/site-packages/wandb/sdk/wandb_init.py", line 1206, in init
    raise e
  File "/home/s2240084/conFEDential/venv/lib/python3.10/site-packages/wandb/sdk/wandb_init.py", line 1183, in init
    wi.setup(kwargs)
  File "/home/s2240084/conFEDential/venv/lib/python3.10/site-packages/wandb/sdk/wandb_init.py", line 190, in setup
    self._wl = wandb_setup.setup(settings=setup_settings)
  File "/home/s2240084/conFEDential/venv/lib/python3.10/site-packages/wandb/sdk/wandb_setup.py", line 327, in setup
    ret = _setup(settings=settings)
  File "/home/s2240084/conFEDential/venv/lib/python3.10/site-packages/wandb/sdk/wandb_setup.py", line 320, in _setup
    wl = _WandbSetup(settings=settings)
  File "/home/s2240084/conFEDential/venv/lib/python3.10/site-packages/wandb/sdk/wandb_setup.py", line 303, in __init__
    _WandbSetup._instance = _WandbSetup__WandbSetup(settings=settings, pid=pid)
  File "/home/s2240084/conFEDential/venv/lib/python3.10/site-packages/wandb/sdk/wandb_setup.py", line 114, in __init__
    self._setup()
  File "/home/s2240084/conFEDential/venv/lib/python3.10/site-packages/wandb/sdk/wandb_setup.py", line 250, in _setup
    self._setup_manager()
  File "/home/s2240084/conFEDential/venv/lib/python3.10/site-packages/wandb/sdk/wandb_setup.py", line 277, in _setup_manager
    self._manager = wandb_manager._Manager(settings=self._settings)
  File "/home/s2240084/conFEDential/venv/lib/python3.10/site-packages/wandb/sdk/wandb_manager.py", line 139, in __init__
    self._service.start()
  File "/home/s2240084/conFEDential/venv/lib/python3.10/site-packages/wandb/sdk/service/service.py", line 250, in start
    self._launch_server()
  File "/home/s2240084/conFEDential/venv/lib/python3.10/site-packages/wandb/sdk/service/service.py", line 244, in _launch_server
    _sentry.reraise(e)
  File "/home/s2240084/conFEDential/venv/lib/python3.10/site-packages/wandb/analytics/sentry.py", line 154, in reraise
    raise exc.with_traceback(sys.exc_info()[2])
  File "/home/s2240084/conFEDential/venv/lib/python3.10/site-packages/wandb/sdk/service/service.py", line 242, in _launch_server
    self._wait_for_ports(fname, proc=internal_proc)
  File "/home/s2240084/conFEDential/venv/lib/python3.10/site-packages/wandb/sdk/service/service.py", line 132, in _wait_for_ports
    raise ServiceStartTimeoutError(
wandb.sdk.service.service.ServiceStartTimeoutError: Timed out waiting for wandb service to start after 30.0 seconds. Try increasing the timeout with the `_service_wait` setting.
Traceback (most recent call last):
  File "/deepstore/software/python/3.10.7/lib/python3.10/runpy.py", line 196, in _run_module_as_main
    return _run_code(code, main_globals, None,
  File "/deepstore/software/python/3.10.7/lib/python3.10/runpy.py", line 86, in _run_code
    exec(code, run_globals)
  File "/home/s2240084/conFEDential/venv/lib/python3.10/site-packages/wandb/__main__.py", line 3, in <module>
    cli.cli(prog_name="python -m wandb")
  File "/home/s2240084/conFEDential/venv/lib/python3.10/site-packages/click/core.py", line 1157, in __call__
    return self.main(*args, **kwargs)
  File "/home/s2240084/conFEDential/venv/lib/python3.10/site-packages/click/core.py", line 1078, in main
    rv = self.invoke(ctx)
  File "/home/s2240084/conFEDential/venv/lib/python3.10/site-packages/click/core.py", line 1688, in invoke
    return _process_result(sub_ctx.command.invoke(sub_ctx))
  File "/home/s2240084/conFEDential/venv/lib/python3.10/site-packages/click/core.py", line 1434, in invoke
    return ctx.invoke(self.callback, **ctx.params)
  File "/home/s2240084/conFEDential/venv/lib/python3.10/site-packages/click/core.py", line 783, in invoke
    return __callback(*args, **kwargs)
  File "/home/s2240084/conFEDential/venv/lib/python3.10/site-packages/wandb/cli/cli.py", line 105, in wrapper
    return func(*args, **kwargs)
  File "/home/s2240084/conFEDential/venv/lib/python3.10/site-packages/wandb/cli/cli.py", line 289, in service
    server.serve()
  File "/home/s2240084/conFEDential/venv/lib/python3.10/site-packages/wandb/sdk/service/server.py", line 114, in serve
    self._inform_used_ports(sock_port=sock_port)
  File "/home/s2240084/conFEDential/venv/lib/python3.10/site-packages/wandb/sdk/service/server.py", line 52, in _inform_used_ports
    pf.write(self._port_fname)
  File "/home/s2240084/conFEDential/venv/lib/python3.10/site-packages/wandb/sdk/service/port_file.py", line 21, in write
    f = tempfile.NamedTemporaryFile(prefix=bname, dir=dname, mode="w", delete=False)
  File "/deepstore/software/python/3.10.7/lib/python3.10/tempfile.py", line 559, in NamedTemporaryFile
    file = _io.open(dir, mode, buffering=buffering,
  File "/deepstore/software/python/3.10.7/lib/python3.10/tempfile.py", line 556, in opener
    fd, name = _mkstemp_inner(dir, prefix, suffix, flags, output_type)
  File "/deepstore/software/python/3.10.7/lib/python3.10/tempfile.py", line 256, in _mkstemp_inner
    fd = _os.open(file, flags, 0o600)
FileNotFoundError: [Errno 2] No such file or directory: '/tmp/tmplupht9f4/port-3255178.txt7hcvtabq'
srun: error: ctit080: task 0: Exited with exit code 1
2024-05-23 14:05:20,142	VINFO scripts.py:1068 -- Send termination request to `/home/s2240084/conFEDential/venv/bin/python -u /home/s2240084/conFEDential/venv/lib/python3.10/site-packages/ray/autoscaler/_private/monitor.py --logs-dir=/local/ray/session_2024-05-23_13-55-49_404658_3253617/logs --logging-rotate-bytes=536870912 --logging-rotate-backup-count=5 --gcs-address=10.20.240.10:6379 --monitor-ip=10.20.240.10` (via SIGTERM)
2024-05-23 14:05:20,142	VINFO scripts.py:1068 -- Send termination request to `/home/s2240084/conFEDential/venv/bin/python -u /home/s2240084/conFEDential/venv/lib/python3.10/site-packages/ray/_private/log_monitor.py --logs-dir=/local/ray/session_2024-05-23_13-55-49_404658_3253617/logs --gcs-address=10.20.240.10:6379 --logging-rotate-bytes=536870912 --logging-rotate-backup-count=5` (via SIGTERM)
2024-05-23 14:05:20,148	VINFO scripts.py:1068 -- Send termination request to `/home/s2240084/conFEDential/venv/bin/python -m ray.util.client.server --address=10.20.240.10:6379 --host=0.0.0.0 --port=10001 --mode=proxy --metrics-agent-port=62926` (via SIGTERM)
2024-05-23 14:05:20,167	VINFO scripts.py:1068 -- Send termination request to `/home/s2240084/conFEDential/venv/bin/python -u /home/s2240084/conFEDential/venv/lib/python3.10/site-packages/ray/_private/log_monitor.py --logs-dir=/local/ray/session_2024-05-23_13-55-49_404658_3253617/logs --gcs-address=10.20.240.10:6379 --logging-rotate-bytes=536870912 --logging-rotate-backup-count=5` (via SIGTERM)
2024-05-23 14:05:20,181	VINFO scripts.py:1068 -- Send termination request to `/home/s2240084/conFEDential/venv/bin/python /home/s2240084/conFEDential/venv/lib/python3.10/site-packages/ray/dashboard/dashboard.py --host=127.0.0.1 --port=8265 --port-retries=0 --temp-dir=/local/ray --log-dir=/local/ray/session_2024-05-23_13-55-49_404658_3253617/logs --session-dir=/local/ray/session_2024-05-23_13-55-49_404658_3253617 --logging-rotate-bytes=536870912 --logging-rotate-backup-count=5 --gcs-address=10.20.240.10:6379 --node-ip-address=10.20.240.10 --minimal` (via SIGTERM)
2024-05-23 14:05:20,445	INFO scripts.py:1098 -- 1/4 stopped.2024-05-23 14:05:20,445	INFO scripts.py:1098 -- 2/4 stopped.2024-05-23 14:05:20,445	INFO scripts.py:1098 -- 3/4 stopped.2024-05-23 14:05:20,778	INFO scripts.py:1098 -- 4/4 stopped.2024-05-23 14:05:20,962	VINFO scripts.py:1068 -- Send termination request to `/home/s2240084/conFEDential/venv/lib/python3.10/site-packages/ray/core/src/ray/gcs/gcs_server --log_dir=/local/ray/session_2024-05-23_13-55-49_404658_3253617/logs --config_list=eyJvYmplY3Rfc3BpbGxpbmdfY29uZmlnIjogIntcInR5cGVcIjogXCJmaWxlc3lzdGVtXCIsIFwicGFyYW1zXCI6IHtcImRpcmVjdG9yeV9wYXRoXCI6IFwiL2xvY2FsL3JheS9zZXNzaW9uXzIwMjQtMDUtMjNfMTMtNTUtNDlfNDA0NjU4XzMyNTM2MTdcIn19IiwgImlzX2V4dGVybmFsX3N0b3JhZ2VfdHlwZV9mcyI6IHRydWV9 --gcs_server_port=6379 --metrics-agent-port=62926 --node-ip-address=10.20.240.10 --session-name=session_2024-05-23_13-55-49_404658_3253617` (via SIGTERM)
2024-05-23 14:05:21,326	INFO scripts.py:1098 -- 1/1 stopped.2024-05-23 14:05:21,327	SUCC scripts.py:1142 -- Stopped all 5 Ray processes.
